[2022-03-16 11:19:30,601 INFO ][Microblog startup  ]
[2022-03-16 11:20:09,026 INFO ][Microblog startup  ]
[2022-03-16 11:28:15,134 INFO ][Microblog startup  ]
[2022-03-16 11:28:53,959 ERROR ][Exception on /edit_profile [POST]  ]
Traceback (most recent call last):
  File "c:\users\home\pycharmprojects\microblog\venv\lib\site-packages\sqlalchemy\engine\base.py", line 1808, in _execute_context
    self.dialect.do_execute(
  File "c:\users\home\pycharmprojects\microblog\venv\lib\site-packages\sqlalchemy\engine\default.py", line 732, in do_execute
    cursor.execute(statement, parameters)
sqlite3.InterfaceError: Error binding parameter 0 - probably unsupported type.

The above exception was the direct cause of the following exception:

Traceback (most recent call last):
  File "c:\users\home\pycharmprojects\microblog\venv\lib\site-packages\flask\app.py", line 2073, in wsgi_app
    response = self.full_dispatch_request()
  File "c:\users\home\pycharmprojects\microblog\venv\lib\site-packages\flask\app.py", line 1518, in full_dispatch_request
    rv = self.handle_user_exception(e)
  File "c:\users\home\pycharmprojects\microblog\venv\lib\site-packages\flask\app.py", line 1516, in full_dispatch_request
    rv = self.dispatch_request()
  File "c:\users\home\pycharmprojects\microblog\venv\lib\site-packages\flask\app.py", line 1502, in dispatch_request
    return self.ensure_sync(self.view_functions[rule.endpoint])(**req.view_args)
  File "C:\Users\Home\PycharmProjects\microblog\app\routes.py", line 96, in edit_profile
    if form.validate_on_submit():
  File "c:\users\home\pycharmprojects\microblog\venv\lib\site-packages\flask_wtf\form.py", line 86, in validate_on_submit
    return self.is_submitted() and self.validate()
  File "c:\users\home\pycharmprojects\microblog\venv\lib\site-packages\wtforms\form.py", line 329, in validate
    return super().validate(extra)
  File "c:\users\home\pycharmprojects\microblog\venv\lib\site-packages\wtforms\form.py", line 146, in validate
    if not field.validate(self, extra):
  File "c:\users\home\pycharmprojects\microblog\venv\lib\site-packages\wtforms\fields\core.py", line 242, in validate
    stop_validation = self._run_validation_chain(form, chain)
  File "c:\users\home\pycharmprojects\microblog\venv\lib\site-packages\wtforms\fields\core.py", line 262, in _run_validation_chain
    validator(form, self)
  File "C:\Users\Home\PycharmProjects\microblog\app\forms.py", line 46, in validate_username
    user = User.query.filter_by(username=username).first()
  File "c:\users\home\pycharmprojects\microblog\venv\lib\site-packages\sqlalchemy\orm\query.py", line 2810, in first
    return self.limit(1)._iter().first()
  File "c:\users\home\pycharmprojects\microblog\venv\lib\site-packages\sqlalchemy\orm\query.py", line 2894, in _iter
    result = self.session.execute(
  File "c:\users\home\pycharmprojects\microblog\venv\lib\site-packages\sqlalchemy\orm\session.py", line 1692, in execute
    result = conn._execute_20(statement, params or {}, execution_options)
  File "c:\users\home\pycharmprojects\microblog\venv\lib\site-packages\sqlalchemy\engine\base.py", line 1620, in _execute_20
    return meth(self, args_10style, kwargs_10style, execution_options)
  File "c:\users\home\pycharmprojects\microblog\venv\lib\site-packages\sqlalchemy\sql\elements.py", line 325, in _execute_on_connection
    return connection._execute_clauseelement(
  File "c:\users\home\pycharmprojects\microblog\venv\lib\site-packages\sqlalchemy\engine\base.py", line 1487, in _execute_clauseelement
    ret = self._execute_context(
  File "c:\users\home\pycharmprojects\microblog\venv\lib\site-packages\sqlalchemy\engine\base.py", line 1851, in _execute_context
    self._handle_dbapi_exception(
  File "c:\users\home\pycharmprojects\microblog\venv\lib\site-packages\sqlalchemy\engine\base.py", line 2032, in _handle_dbapi_exception
    util.raise_(
  File "c:\users\home\pycharmprojects\microblog\venv\lib\site-packages\sqlalchemy\util\compat.py", line 207, in raise_
    raise exception
  File "c:\users\home\pycharmprojects\microblog\venv\lib\site-packages\sqlalchemy\engine\base.py", line 1808, in _execute_context
    self.dialect.do_execute(
  File "c:\users\home\pycharmprojects\microblog\venv\lib\site-packages\sqlalchemy\engine\default.py", line 732, in do_execute
    cursor.execute(statement, parameters)
sqlalchemy.exc.InterfaceError: (sqlite3.InterfaceError) Error binding parameter 0 - probably unsupported type.
[SQL: SELECT user.id AS user_id, user.username AS user_username, user.email AS user_email, user.password_hash AS user_password_hash, user.about_me AS user_about_me, user.last_seen AS user_last_seen 
FROM user 
WHERE user.username = ?
 LIMIT ? OFFSET ?]
[parameters: (<wtforms.fields.simple.StringField object at 0x000001A4089B4370>, 1, 0)]
(Background on this error at: https://sqlalche.me/e/14/rvf5)
[2022-03-16 11:29:41,285 INFO ][Microblog startup  ]
[2022-03-16 11:29:49,355 ERROR ][Exception on /edit_profile [POST]  ]
Traceback (most recent call last):
  File "c:\users\home\pycharmprojects\microblog\venv\lib\site-packages\sqlalchemy\engine\base.py", line 1808, in _execute_context
    self.dialect.do_execute(
  File "c:\users\home\pycharmprojects\microblog\venv\lib\site-packages\sqlalchemy\engine\default.py", line 732, in do_execute
    cursor.execute(statement, parameters)
sqlite3.InterfaceError: Error binding parameter 0 - probably unsupported type.

The above exception was the direct cause of the following exception:

Traceback (most recent call last):
  File "c:\users\home\pycharmprojects\microblog\venv\lib\site-packages\flask\app.py", line 2073, in wsgi_app
    response = self.full_dispatch_request()
  File "c:\users\home\pycharmprojects\microblog\venv\lib\site-packages\flask\app.py", line 1518, in full_dispatch_request
    rv = self.handle_user_exception(e)
  File "c:\users\home\pycharmprojects\microblog\venv\lib\site-packages\flask\app.py", line 1516, in full_dispatch_request
    rv = self.dispatch_request()
  File "c:\users\home\pycharmprojects\microblog\venv\lib\site-packages\flask\app.py", line 1502, in dispatch_request
    return self.ensure_sync(self.view_functions[rule.endpoint])(**req.view_args)
  File "C:\Users\Home\PycharmProjects\microblog\app\routes.py", line 96, in edit_profile
    if form.validate_on_submit():
  File "c:\users\home\pycharmprojects\microblog\venv\lib\site-packages\flask_wtf\form.py", line 86, in validate_on_submit
    return self.is_submitted() and self.validate()
  File "c:\users\home\pycharmprojects\microblog\venv\lib\site-packages\wtforms\form.py", line 329, in validate
    return super().validate(extra)
  File "c:\users\home\pycharmprojects\microblog\venv\lib\site-packages\wtforms\form.py", line 146, in validate
    if not field.validate(self, extra):
  File "c:\users\home\pycharmprojects\microblog\venv\lib\site-packages\wtforms\fields\core.py", line 242, in validate
    stop_validation = self._run_validation_chain(form, chain)
  File "c:\users\home\pycharmprojects\microblog\venv\lib\site-packages\wtforms\fields\core.py", line 262, in _run_validation_chain
    validator(form, self)
  File "C:\Users\Home\PycharmProjects\microblog\app\forms.py", line 46, in validate_username
    user = User.query.filter_by(username=username).first()
  File "c:\users\home\pycharmprojects\microblog\venv\lib\site-packages\sqlalchemy\orm\query.py", line 2810, in first
    return self.limit(1)._iter().first()
  File "c:\users\home\pycharmprojects\microblog\venv\lib\site-packages\sqlalchemy\orm\query.py", line 2894, in _iter
    result = self.session.execute(
  File "c:\users\home\pycharmprojects\microblog\venv\lib\site-packages\sqlalchemy\orm\session.py", line 1692, in execute
    result = conn._execute_20(statement, params or {}, execution_options)
  File "c:\users\home\pycharmprojects\microblog\venv\lib\site-packages\sqlalchemy\engine\base.py", line 1620, in _execute_20
    return meth(self, args_10style, kwargs_10style, execution_options)
  File "c:\users\home\pycharmprojects\microblog\venv\lib\site-packages\sqlalchemy\sql\elements.py", line 325, in _execute_on_connection
    return connection._execute_clauseelement(
  File "c:\users\home\pycharmprojects\microblog\venv\lib\site-packages\sqlalchemy\engine\base.py", line 1487, in _execute_clauseelement
    ret = self._execute_context(
  File "c:\users\home\pycharmprojects\microblog\venv\lib\site-packages\sqlalchemy\engine\base.py", line 1851, in _execute_context
    self._handle_dbapi_exception(
  File "c:\users\home\pycharmprojects\microblog\venv\lib\site-packages\sqlalchemy\engine\base.py", line 2032, in _handle_dbapi_exception
    util.raise_(
  File "c:\users\home\pycharmprojects\microblog\venv\lib\site-packages\sqlalchemy\util\compat.py", line 207, in raise_
    raise exception
  File "c:\users\home\pycharmprojects\microblog\venv\lib\site-packages\sqlalchemy\engine\base.py", line 1808, in _execute_context
    self.dialect.do_execute(
  File "c:\users\home\pycharmprojects\microblog\venv\lib\site-packages\sqlalchemy\engine\default.py", line 732, in do_execute
    cursor.execute(statement, parameters)
sqlalchemy.exc.InterfaceError: (sqlite3.InterfaceError) Error binding parameter 0 - probably unsupported type.
[SQL: SELECT user.id AS user_id, user.username AS user_username, user.email AS user_email, user.password_hash AS user_password_hash, user.about_me AS user_about_me, user.last_seen AS user_last_seen 
FROM user 
WHERE user.username = ?
 LIMIT ? OFFSET ?]
[parameters: (<wtforms.fields.simple.StringField object at 0x0000025840178130>, 1, 0)]
(Background on this error at: https://sqlalche.me/e/14/rvf5)
